<?xml version="1.0" encoding="utf-8"?>
<!-- This URDF was automatically created by SolidWorks to URDF Exporter! Originally created by Stephen Brawner (brawner@gmail.com) 
     Commit Version: 1.6.0-4-g7f85cfe  Build Version: 1.6.7995.38578
     For more information, please see http://wiki.ros.org/sw_urdf_exporter -->
<robot
  name="elkapod_left_leg_description">
  <link
    name="base_link">
    <inertial>
      <origin
        xyz="-0.023995 0.00067316 0.061186"
        rpy="0 0 0" />
      <mass
        value="0.13339" />
      <inertia
        ixx="4.049E-05"
        ixy="-2.1551E-09"
        ixz="-1.4138E-06"
        iyy="5.3078E-05"
        iyz="-4.4082E-07"
        izz="2.339E-05" />
    </inertial>
    <visual>
      <origin
        xyz="0 0 0"
        rpy="0 0 0" />
      <geometry>
        <mesh
          filename="package://elkapod_left_leg_description/meshes/base_link.STL" />
      </geometry>
      <material
        name="">
        <color
          rgba="0.9098 0.44314 0.031373 1" />
      </material>
    </visual>
    <collision>
      <origin
        xyz="0 0 0"
        rpy="0 0 0" />
      <geometry>
        <mesh
          filename="package://elkapod_left_leg_description/meshes/base_link.STL" />
      </geometry>
    </collision>
  </link>
  <link
    name="linkA">
    <inertial>
      <origin
        xyz="0.0338 -0.00016372 0.00013128"
        rpy="0 0 0" />
      <mass
        value="0.021666" />
      <inertia
        ixx="8.8529E-06"
        ixy="-1.789E-15"
        ixz="1.789E-15"
        iyy="7.5021E-06"
        iyz="3.1856E-21"
        izz="7.5021E-06" />
    </inertial>
    <visual>
      <origin
        xyz="0 0 0"
        rpy="0 0 0" />
      <geometry>
        <mesh
          filename="package://elkapod_left_leg_description/meshes/linkA.STL" />
      </geometry>
      <material
        name="">
        <color
          rgba="0.89804 0.91765 0.92941 1" />
      </material>
    </visual>
    <collision>
      <origin
        xyz="0 0 0"
        rpy="0 0 0" />
      <geometry>
        <mesh
          filename="package://elkapod_left_leg_description/meshes/linkA.STL" />
      </geometry>
    </collision>
  </link>
  <joint
    name="J1"
    type="revolute">
    <origin
      xyz="0 0 0.08213"
      rpy="0 0 0" />
    <parent
      link="base_link" />
    <child
      link="linkA" />
    <axis
      xyz="0 0 1" />
    <limit
      lower="-1.5708"
      upper="1.5708"
      effort="1000"
      velocity="1" />
  </joint>
  <link
    name="linkB">
    <inertial>
      <origin
        xyz="0.045774 0.0084104 -0.0045551"
        rpy="0 0 0" />
      <mass
        value="0.16964" />
      <inertia
        ixx="3.1577E-05"
        ixy="-5.3775E-06"
        ixz="-1.145E-07"
        iyy="4.6936E-05"
        iyz="3.6314E-07"
        izz="3.6054E-05" />
    </inertial>
    <visual>
      <origin
        xyz="0 0 0"
        rpy="0 0 0" />
      <geometry>
        <mesh
          filename="package://elkapod_left_leg_description/meshes/linkB.STL" />
      </geometry>
      <material
        name="">
        <color
          rgba="0.9098 0.44314 0.031373 1" />
      </material>
    </visual>
    <collision>
      <origin
        xyz="0 0 0"
        rpy="0 0 0" />
      <geometry>
        <mesh
          filename="package://elkapod_left_leg_description/meshes/linkB.STL" />
      </geometry>
    </collision>
  </link>
  <joint
    name="J2"
    type="revolute">
    <origin
      xyz="0.0676 0 0"
      rpy="-1.5708 0 0" />
    <parent
      link="linkA" />
    <child
      link="linkB" />
    <axis
      xyz="0 0 -1" />
    <limit
      lower="-1.5708"
      upper="1.5708"
      effort="1000"
      velocity="1" />
  </joint>
  <link
    name="linkC">
    <inertial>
      <origin
        xyz="0.069973 0.083595 -0.00028657"
        rpy="0 0 0" />
      <mass
        value="0.10738" />
      <inertia
        ixx="0.00013282"
        ixy="-7.0822E-05"
        ixz="-8.8457E-07"
        iyy="7.4339E-05"
        iyz="-9.307E-07"
        izz="0.00017244" />
    </inertial>
    <visual>
      <origin
        xyz="0 0 0"
        rpy="0 0 0" />
      <geometry>
        <mesh
          filename="package://elkapod_left_leg_description/meshes/linkC.STL" />
      </geometry>
      <material
        name="">
        <color
          rgba="0.29804 0.29804 0.29804 1" />
      </material>
    </visual>
    <collision>
      <origin
        xyz="0 0 0"
        rpy="0 0 0" />
      <geometry>
        <mesh
          filename="package://elkapod_left_leg_description/meshes/linkC.STL" />
      </geometry>
    </collision>
  </link>
  <joint
    name="J3"
    type="revolute">
    <origin
      xyz="0.088094 0.027776 0"
      rpy="0 0 0" />
    <parent
      link="linkB" />
    <child
      link="linkC" />
    <axis
      xyz="0 0 -1" />
    <limit
      lower="-3.1416"
      upper="0"
      effort="1000"
      velocity="1" />
  </joint>
  <link
    name="FCP">
    <inertial>
      <origin
        xyz="-0.1792 -0.0013596 0.18198"
        rpy="0 0 0" />
      <mass
        value="0.4322" />
      <inertia
        ixx="0.0014604"
        ixy="2.7945E-05"
        ixz="0.0015415"
        iyy="0.0056803"
        iyz="1.8055E-05"
        izz="0.0044097" />
    </inertial>
    <visual>
      <origin
        xyz="0 0 0"
        rpy="0 0 0" />
    </visual>
  </link>
  <joint
    name="fcp_fixed"
    type="fixed">
    <origin
      xyz="0.11837 0.19163 -0.0003"
      rpy="1.5708 0 0" />
    <parent
      link="linkC" />
    <child
      link="FCP" />
    <axis
      xyz="0 0 0" />
  </joint>
</robot>